<?xml version="1.0" ?>
<robot name="aerial_arm" xmlns:xacro="http://www.ros.org/wiki/xacro">

<xacro:include filename="$(find arm_description)/urdf/materials.xacro" />
<xacro:include filename="$(find arm_description)/urdf/aerial_arm.trans" />
<xacro:include filename="$(find arm_description)/urdf/aerial_arm.gazebo" />

<joint name="orientation_joint" type="fixed">
  <parent link="hummingbird/base_link"/>
  <child link="orientation_link"/>
  <origin rpy="${pi/2} 0 -1" xyz="0 0 -0.06"/>
</joint>

<link name="orientation_link"/>

<joint name="base_arm_joint" type="fixed">
  <parent link="orientation_link"/>
  <child link="arm_base_link"/>
  <origin rpy="0 0 0" xyz="0.011623 -0.033576 -0.423212"/>
</joint>

<link name="arm_base_link">
  <inertial>
    <origin rpy="0 0 0" xyz="-0.011622835562823751 0.026076416772968965 0.4232115499965129"/>
    <mass value="0.6539245694270445"/>
    <inertia ixx="0.00013" ixy="0.0" ixz="0.0" iyy="0.000235" iyz="-0.0" izz="0.00013"/>
  </inertial>
  <visual>
    <origin rpy="0 0 0" xyz="0 0 0"/>
    <geometry>
      <mesh filename="package://arm_description/meshes/base_link.stl" scale="0.001 0.001 0.001"/>
    </geometry>
    <material name="silver"/>
  </visual>
  <collision>
    <origin rpy="0 0 0" xyz="0 0 0"/>
    <geometry>
      <mesh filename="package://arm_description/meshes/base_link.stl" scale="0.001 0.001 0.001"/>
    </geometry>
  </collision>
</link>

<link name="shoulder_2_1">
  <inertial>
    <origin rpy="0 0 0" xyz="-7.295146686063514e-06 -0.03272366123986107 8.378471211212268e-06"/>
    <mass value="0.18907008597028982"/>
    <inertia ixx="8.7e-05" ixy="0.0" ixz="0.0" iyy="8.1e-05" iyz="-0.0" izz="6.5e-05"/>
  </inertial>
  <visual>
    <origin rpy="0 0 0" xyz="0.011623 -0.033576 -0.423212"/>
    <geometry>
      <mesh filename="package://arm_description/meshes/shoulder_2_1.stl" scale="0.001 0.001 0.001"/>
    </geometry>
    <material name="silver"/>
  </visual>
  <collision>
    <origin rpy="0 0 0" xyz="0.011623 -0.033576 -0.423212"/>
    <geometry>
      <mesh filename="package://arm_description/meshes/shoulder_2_1.stl" scale="0.001 0.001 0.001"/>
    </geometry>
  </collision>
</link>

<gazebo reference="shoulder_2_1">
  <kp>1000000.0</kp>
  <kd>1000.0</kd>
  <mu1>0.8</mu1>
  <mu2>0.8</mu2>
  <maxVel>0.0</maxVel>
  <minDepth>0.001</minDepth>
</gazebo>

<link name="first_Link_200_1">
  <inertial>
    <origin rpy="0 0 0" xyz="0.01000015992057332 4.0839001024493837e-07 -0.10000041458331238"/>
    <mass value="0.04111040389630535"/>
    <inertia ixx="0.000248" ixy="-0.0" ixz="-0.0" iyy="0.000248" iyz="0.0" izz="3e-06"/>
  </inertial>
  <visual>
    <origin rpy="0 0 0" xyz="0.021623 0.001424 -0.423212"/>
    <geometry>
      <mesh filename="package://arm_description/meshes/first_Link_200_1.stl" scale="0.001 0.001 0.001"/>
    </geometry>
    <material name="silver"/>
  </visual>
  <collision>
    <origin rpy="0 0 0" xyz="0.021623 0.001424 -0.423212"/>
    <geometry>
      <mesh filename="package://arm_description/meshes/first_Link_200_1.stl" scale="0.001 0.001 0.001"/>
    </geometry>
  </collision>
</link>

<link name="second_Link_200__1__1">
  <inertial>
    <origin rpy="0 0 0" xyz="0.010000158743883165 4.123575158946919e-07 -0.07070574631913057"/>
    <mass value="0.031775151367082886"/>
    <inertia ixx="0.000128" ixy="-0.0" ixz="0.0" iyy="0.000128" iyz="0.0" izz="2e-06"/>
  </inertial>
  <visual>
    <origin rpy="0 0 0" xyz="0.041623 0.001424 -0.223212"/>
    <geometry>
      <mesh filename="package://arm_description/meshes/second_Link_200__1__1.stl" scale="0.001 0.001 0.001"/>
    </geometry>
    <material name="silver"/>
  </visual>
  <collision>
    <origin rpy="0 0 0" xyz="0.041623 0.001424 -0.223212"/>
    <geometry>
      <mesh filename="package://arm_description/meshes/second_Link_200__1__1.stl" scale="0.001 0.001 0.001"/>
    </geometry>
  </collision>
</link>

<link name="Yaw_1">
  <inertial>
    <origin rpy="0 0 0" xyz="1.6443717608394248e-07 4.10947984520911e-07 -0.009712908448932418"/>
    <mass value="0.019335321488620901"/>
    <inertia ixx="0.0" ixy="0.0" ixz="0.0" iyy="1e-06" iyz="0.0" izz="1e-06"/>
  </inertial>
  <visual>
    <origin rpy="0 0 0" xyz="0.031623 0.001424 -0.033212"/>
    <geometry>
      <mesh filename="package://arm_description/meshes/Yaw_1.stl" scale="0.001 0.001 0.001"/>
    </geometry>
    <material name="silver"/>
  </visual>
  <collision>
    <origin rpy="0 0 0" xyz="0.031623 0.001424 -0.033212"/>
    <geometry>
      <mesh filename="package://arm_description/meshes/Yaw_1.stl" scale="0.001 0.001 0.001"/>
    </geometry>
  </collision>
</link>

<link name="Pitch_1">
  <inertial>
    <origin rpy="0 0 0" xyz="0.012000164437172327 4.1677296895841626e-07 -0.00730630929765641"/>
    <mass value="0.017370138299177099"/>
    <inertia ixx="1e-02" ixy="0.0" ixz="-0.0" iyy="1e-02" iyz="-0.0" izz="1e-02"/>
  </inertial>
  <visual>
    <origin rpy="0 0 0" xyz="0.043623 0.001424 -0.023212"/>
    <geometry>
      <mesh filename="package://arm_description/meshes/Pitch_1.stl" scale="0.001 0.001 0.001"/>
    </geometry>
    <material name="silver"/>
  </visual>
 <!-- <collision>
    <origin rpy="0 0 0" xyz="0.043623 0.001424 -0.023212"/>
    <geometry>
      <mesh filename="package://arm_description/meshes/Pitch_1.stl" scale="0.001 0.001 0.001"/>
    </geometry>
  </collision> -->
</link>


<link name="Roll_1">
  <inertial>
    <origin rpy="0 0 0" xyz="1.6443717608394248e-07 4.1677296895668153e-07 0.007499957912210709"/>
    <mass value="0.016738716241950105"/>
    <inertia ixx="1e-02" ixy="0.0" ixz="-0.0" iyy="1e-02" iyz="-0.0" izz="1e-02"/>
  </inertial>
  <visual>
    <origin rpy="0 0 0" xyz="0.031623 0.001424 0.00881"/>
    <geometry>
      <mesh filename="package://arm_description/meshes/Roll_1.stl" scale="0.001 0.001 0.001"/>
    </geometry>
    <material name="silver"/>
  </visual>
 <!-- <collision>
    <origin rpy="0 0 0" xyz="0.031623 0.001424 0.00881"/>
    <geometry>
      <mesh filename="package://arm_description/meshes/Roll_1.stl" scale="0.001 0.001 0.001"/>
    </geometry>
  </collision> -->
</link>


<xacro:property name="limit" value="100" />

<joint name="Rev3" type="revolute">
  <origin rpy="0 0 0" xyz="-0.011623 0.033576 0.423212"/>
  <parent link="arm_base_link"/>
  <child link="shoulder_2_1"/>
  <axis xyz="0.0 1.0 -0.0"/>
  <limit
      lower="-3.1415"
      upper="3.1415"
      effort="5"
      velocity="1.57"
   />
</joint>

<joint name="Rev4" type="revolute">
  <origin rpy="0 0 0" xyz="-0.01 -0.035 0.0"/>
  <parent link="shoulder_2_1"/>
  <child link="first_Link_200_1"/>
  <axis xyz="1.0 0.0 0.0"/>
 <limit
      lower="-3.1415"
      upper="3.1415"
      effort="5"
      velocity="1.57"
   />
</joint>

<joint name="Rev5" type="revolute">
  <origin rpy="0 0 0" xyz="-0.02 0.0 -0.2"/>
  <parent link="first_Link_200_1"/>
  <child link="second_Link_200__1__1"/>
  <axis xyz="1.0 0.0 0.0"/>
 <limit
      lower="-3.1415"
      upper="3.1415"
      effort="5"
      velocity="1.57"
   />
</joint>


<joint name="Rev6" type="revolute">
  <origin rpy="0 0 0" xyz="0.01 0.0 -0.19"/>
  <parent link="second_Link_200__1__1"/>
  <child link="Yaw_1"/>
  <axis xyz="0.0 0.0 1.0"/>
 <limit
      lower="-3.1415"
      upper="3.1415"
      effort="5"
      velocity="1.57"
   />
</joint>

<joint name="Rev7" type="revolute">
  <origin rpy="0 0 0" xyz="-0.012 0.0 -0.01"/>
  <parent link="Yaw_1"/>
  <child link="Pitch_1"/>
  <axis xyz="1.0 -0.0 0.0"/>
 <limit
      lower="-3.1415"
      upper="3.1415"
      effort="5"
      velocity="1.57"
   />
</joint>


<joint name="Rev8" type="revolute">
  <origin rpy="0 0 0" xyz="0.012 0.0 -0.032022"/>
  <parent link="Pitch_1"/>
  <child link="Roll_1"/>
  <axis xyz="-0.0 -0.0 -1.0"/>
 <limit
      lower="-3.1415"
      upper="3.1415"
      effort="5"
      velocity="1.57"
   />
</joint>


</robot>
